Traceback (most recent call last):
  File "C:\Users\sayala\AppData\Roaming\Python\Python311\site-packages\jupyter_cache\executors\utils.py", line 58, in single_nb_execution
    executenb(
  File "C:\Users\sayala\AppData\Roaming\Python\Python311\site-packages\nbclient\client.py", line 1305, in execute
    return NotebookClient(nb=nb, resources=resources, km=km, **kwargs).execute()
           ^^^^^^^^^^^^^^^^^^^^^^^^^^^^^^^^^^^^^^^^^^^^^^^^^^^^^^^^^^^^^^^^^^^^^
  File "C:\ProgramData\Anaconda3\Lib\site-packages\jupyter_core\utils\__init__.py", line 173, in wrapped
    return loop.run_until_complete(inner)
           ^^^^^^^^^^^^^^^^^^^^^^^^^^^^^^
  File "C:\ProgramData\Anaconda3\Lib\asyncio\base_events.py", line 653, in run_until_complete
    return future.result()
           ^^^^^^^^^^^^^^^
  File "C:\Users\sayala\AppData\Roaming\Python\Python311\site-packages\nbclient\client.py", line 705, in async_execute
    await self.async_execute_cell(
  File "C:\Users\sayala\AppData\Roaming\Python\Python311\site-packages\nbclient\client.py", line 1058, in async_execute_cell
    await self._check_raise_for_error(cell, cell_index, exec_reply)
  File "C:\Users\sayala\AppData\Roaming\Python\Python311\site-packages\nbclient\client.py", line 914, in _check_raise_for_error
    raise CellExecutionError.from_cell_and_msg(cell, exec_reply_content)
nbclient.exceptions.CellExecutionError: An error occurred while executing the following cell:
------------------
df_tmy, metadata = pvlib.iotools.get_psm3(
    latitude=39.7407, longitude=-105.1686,
    api_key=NREL_API_KEY,
    email='silvana.ovaitt@nrel.gov',  # <-- any email works here fine
    names='tmy')
metadata


------------------


[1;31m---------------------------------------------------------------------------[0m
[1;31mSSLCertVerificationError[0m                  Traceback (most recent call last)
File [1;32mC:\ProgramData\Anaconda3\Lib\site-packages\urllib3\connectionpool.py:715[0m, in [0;36mHTTPConnectionPool.urlopen[1;34m(self, method, url, body, headers, retries, redirect, assert_same_host, timeout, pool_timeout, release_conn, chunked, body_pos, **response_kw)[0m
[0;32m    714[0m [38;5;66;03m# Make the request on the httplib connection object.[39;00m
[1;32m--> 715[0m httplib_response [38;5;241m=[39m [38;5;28mself[39m[38;5;241m.[39m_make_request(
[0;32m    716[0m     conn,
[0;32m    717[0m     method,
[0;32m    718[0m     url,
[0;32m    719[0m     timeout[38;5;241m=[39mtimeout_obj,
[0;32m    720[0m     body[38;5;241m=[39mbody,
[0;32m    721[0m     headers[38;5;241m=[39mheaders,
[0;32m    722[0m     chunked[38;5;241m=[39mchunked,
[0;32m    723[0m )
[0;32m    725[0m [38;5;66;03m# If we're going to release the connection in ``finally:``, then[39;00m
[0;32m    726[0m [38;5;66;03m# the response doesn't need to know about the connection. Otherwise[39;00m
[0;32m    727[0m [38;5;66;03m# it will also try to release it and we'll have a double-release[39;00m
[0;32m    728[0m [38;5;66;03m# mess.[39;00m

File [1;32mC:\ProgramData\Anaconda3\Lib\site-packages\urllib3\connectionpool.py:404[0m, in [0;36mHTTPConnectionPool._make_request[1;34m(self, conn, method, url, timeout, chunked, **httplib_request_kw)[0m
[0;32m    403[0m [38;5;28;01mtry[39;00m:
[1;32m--> 404[0m     [38;5;28mself[39m[38;5;241m.[39m_validate_conn(conn)
[0;32m    405[0m [38;5;28;01mexcept[39;00m (SocketTimeout, BaseSSLError) [38;5;28;01mas[39;00m e:
[0;32m    406[0m     [38;5;66;03m# Py2 raises this as a BaseSSLError, Py3 raises it as socket timeout.[39;00m

File [1;32mC:\ProgramData\Anaconda3\Lib\site-packages\urllib3\connectionpool.py:1058[0m, in [0;36mHTTPSConnectionPool._validate_conn[1;34m(self, conn)[0m
[0;32m   1057[0m [38;5;28;01mif[39;00m [38;5;129;01mnot[39;00m [38;5;28mgetattr[39m(conn, [38;5;124m"[39m[38;5;124msock[39m[38;5;124m"[39m, [38;5;28;01mNone[39;00m):  [38;5;66;03m# AppEngine might not have  `.sock`[39;00m
[1;32m-> 1058[0m     conn[38;5;241m.[39mconnect()
[0;32m   1060[0m [38;5;28;01mif[39;00m [38;5;129;01mnot[39;00m conn[38;5;241m.[39mis_verified:

File [1;32mC:\ProgramData\Anaconda3\Lib\site-packages\urllib3\connection.py:419[0m, in [0;36mHTTPSConnection.connect[1;34m(self)[0m
[0;32m    417[0m     context[38;5;241m.[39mload_default_certs()
[1;32m--> 419[0m [38;5;28mself[39m[38;5;241m.[39msock [38;5;241m=[39m ssl_wrap_socket(
[0;32m    420[0m     sock[38;5;241m=[39mconn,
[0;32m    421[0m     keyfile[38;5;241m=[39m[38;5;28mself[39m[38;5;241m.[39mkey_file,
[0;32m    422[0m     certfile[38;5;241m=[39m[38;5;28mself[39m[38;5;241m.[39mcert_file,
[0;32m    423[0m     key_password[38;5;241m=[39m[38;5;28mself[39m[38;5;241m.[39mkey_password,
[0;32m    424[0m     ca_certs[38;5;241m=[39m[38;5;28mself[39m[38;5;241m.[39mca_certs,
[0;32m    425[0m     ca_cert_dir[38;5;241m=[39m[38;5;28mself[39m[38;5;241m.[39mca_cert_dir,
[0;32m    426[0m     ca_cert_data[38;5;241m=[39m[38;5;28mself[39m[38;5;241m.[39mca_cert_data,
[0;32m    427[0m     server_hostname[38;5;241m=[39mserver_hostname,
[0;32m    428[0m     ssl_context[38;5;241m=[39mcontext,
[0;32m    429[0m     tls_in_tls[38;5;241m=[39mtls_in_tls,
[0;32m    430[0m )
[0;32m    432[0m [38;5;66;03m# If we're using all defaults and the connection[39;00m
[0;32m    433[0m [38;5;66;03m# is TLSv1 or TLSv1.1 we throw a DeprecationWarning[39;00m
[0;32m    434[0m [38;5;66;03m# for the host.[39;00m

File [1;32mC:\ProgramData\Anaconda3\Lib\site-packages\urllib3\util\ssl_.py:449[0m, in [0;36mssl_wrap_socket[1;34m(sock, keyfile, certfile, cert_reqs, ca_certs, server_hostname, ssl_version, ciphers, ssl_context, ca_cert_dir, key_password, ca_cert_data, tls_in_tls)[0m
[0;32m    448[0m [38;5;28;01mif[39;00m send_sni:
[1;32m--> 449[0m     ssl_sock [38;5;241m=[39m _ssl_wrap_socket_impl(
[0;32m    450[0m         sock, context, tls_in_tls, server_hostname[38;5;241m=[39mserver_hostname
[0;32m    451[0m     )
[0;32m    452[0m [38;5;28;01melse[39;00m:

File [1;32mC:\ProgramData\Anaconda3\Lib\site-packages\urllib3\util\ssl_.py:493[0m, in [0;36m_ssl_wrap_socket_impl[1;34m(sock, ssl_context, tls_in_tls, server_hostname)[0m
[0;32m    492[0m [38;5;28;01mif[39;00m server_hostname:
[1;32m--> 493[0m     [38;5;28;01mreturn[39;00m ssl_context[38;5;241m.[39mwrap_socket(sock, server_hostname[38;5;241m=[39mserver_hostname)
[0;32m    494[0m [38;5;28;01melse[39;00m:

File [1;32mC:\ProgramData\Anaconda3\Lib\ssl.py:517[0m, in [0;36mSSLContext.wrap_socket[1;34m(self, sock, server_side, do_handshake_on_connect, suppress_ragged_eofs, server_hostname, session)[0m
[0;32m    511[0m [38;5;28;01mdef[39;00m [38;5;21mwrap_socket[39m([38;5;28mself[39m, sock, server_side[38;5;241m=[39m[38;5;28;01mFalse[39;00m,
[0;32m    512[0m                 do_handshake_on_connect[38;5;241m=[39m[38;5;28;01mTrue[39;00m,
[0;32m    513[0m                 suppress_ragged_eofs[38;5;241m=[39m[38;5;28;01mTrue[39;00m,
[0;32m    514[0m                 server_hostname[38;5;241m=[39m[38;5;28;01mNone[39;00m, session[38;5;241m=[39m[38;5;28;01mNone[39;00m):
[0;32m    515[0m     [38;5;66;03m# SSLSocket class handles server_hostname encoding before it calls[39;00m
[0;32m    516[0m     [38;5;66;03m# ctx._wrap_socket()[39;00m
[1;32m--> 517[0m     [38;5;28;01mreturn[39;00m [38;5;28mself[39m[38;5;241m.[39msslsocket_class[38;5;241m.[39m_create(
[0;32m    518[0m         sock[38;5;241m=[39msock,
[0;32m    519[0m         server_side[38;5;241m=[39mserver_side,
[0;32m    520[0m         do_handshake_on_connect[38;5;241m=[39mdo_handshake_on_connect,
[0;32m    521[0m         suppress_ragged_eofs[38;5;241m=[39msuppress_ragged_eofs,
[0;32m    522[0m         server_hostname[38;5;241m=[39mserver_hostname,
[0;32m    523[0m         context[38;5;241m=[39m[38;5;28mself[39m,
[0;32m    524[0m         session[38;5;241m=[39msession
[0;32m    525[0m     )

File [1;32mC:\ProgramData\Anaconda3\Lib\ssl.py:1108[0m, in [0;36mSSLSocket._create[1;34m(cls, sock, server_side, do_handshake_on_connect, suppress_ragged_eofs, server_hostname, context, session)[0m
[0;32m   1107[0m             [38;5;28;01mraise[39;00m [38;5;167;01mValueError[39;00m([38;5;124m"[39m[38;5;124mdo_handshake_on_connect should not be specified for non-blocking sockets[39m[38;5;124m"[39m)
[1;32m-> 1108[0m         [38;5;28mself[39m[38;5;241m.[39mdo_handshake()
[0;32m   1109[0m [38;5;28;01mexcept[39;00m ([38;5;167;01mOSError[39;00m, [38;5;167;01mValueError[39;00m):

File [1;32mC:\ProgramData\Anaconda3\Lib\ssl.py:1383[0m, in [0;36mSSLSocket.do_handshake[1;34m(self, block)[0m
[0;32m   1382[0m         [38;5;28mself[39m[38;5;241m.[39msettimeout([38;5;28;01mNone[39;00m)
[1;32m-> 1383[0m     [38;5;28mself[39m[38;5;241m.[39m_sslobj[38;5;241m.[39mdo_handshake()
[0;32m   1384[0m [38;5;28;01mfinally[39;00m:

[1;31mSSLCertVerificationError[0m: [SSL: CERTIFICATE_VERIFY_FAILED] certificate verify failed: self-signed certificate in certificate chain (_ssl.c:1006)

During handling of the above exception, another exception occurred:

[1;31mMaxRetryError[0m                             Traceback (most recent call last)
File [1;32m~\AppData\Roaming\Python\Python311\site-packages\requests\adapters.py:486[0m, in [0;36mHTTPAdapter.send[1;34m(self, request, stream, timeout, verify, cert, proxies)[0m
[0;32m    485[0m [38;5;28;01mtry[39;00m:
[1;32m--> 486[0m     resp [38;5;241m=[39m conn[38;5;241m.[39murlopen(
[0;32m    487[0m         method[38;5;241m=[39mrequest[38;5;241m.[39mmethod,
[0;32m    488[0m         url[38;5;241m=[39murl,
[0;32m    489[0m         body[38;5;241m=[39mrequest[38;5;241m.[39mbody,
[0;32m    490[0m         headers[38;5;241m=[39mrequest[38;5;241m.[39mheaders,
[0;32m    491[0m         redirect[38;5;241m=[39m[38;5;28;01mFalse[39;00m,
[0;32m    492[0m         assert_same_host[38;5;241m=[39m[38;5;28;01mFalse[39;00m,
[0;32m    493[0m         preload_content[38;5;241m=[39m[38;5;28;01mFalse[39;00m,
[0;32m    494[0m         decode_content[38;5;241m=[39m[38;5;28;01mFalse[39;00m,
[0;32m    495[0m         retries[38;5;241m=[39m[38;5;28mself[39m[38;5;241m.[39mmax_retries,
[0;32m    496[0m         timeout[38;5;241m=[39mtimeout,
[0;32m    497[0m         chunked[38;5;241m=[39mchunked,
[0;32m    498[0m     )
[0;32m    500[0m [38;5;28;01mexcept[39;00m (ProtocolError, [38;5;167;01mOSError[39;00m) [38;5;28;01mas[39;00m err:

File [1;32mC:\ProgramData\Anaconda3\Lib\site-packages\urllib3\connectionpool.py:799[0m, in [0;36mHTTPConnectionPool.urlopen[1;34m(self, method, url, body, headers, retries, redirect, assert_same_host, timeout, pool_timeout, release_conn, chunked, body_pos, **response_kw)[0m
[0;32m    797[0m     e [38;5;241m=[39m ProtocolError([38;5;124m"[39m[38;5;124mConnection aborted.[39m[38;5;124m"[39m, e)
[1;32m--> 799[0m retries [38;5;241m=[39m retries[38;5;241m.[39mincrement(
[0;32m    800[0m     method, url, error[38;5;241m=[39me, _pool[38;5;241m=[39m[38;5;28mself[39m, _stacktrace[38;5;241m=[39msys[38;5;241m.[39mexc_info()[[38;5;241m2[39m]
[0;32m    801[0m )
[0;32m    802[0m retries[38;5;241m.[39msleep()

File [1;32mC:\ProgramData\Anaconda3\Lib\site-packages\urllib3\util\retry.py:592[0m, in [0;36mRetry.increment[1;34m(self, method, url, response, error, _pool, _stacktrace)[0m
[0;32m    591[0m [38;5;28;01mif[39;00m new_retry[38;5;241m.[39mis_exhausted():
[1;32m--> 592[0m     [38;5;28;01mraise[39;00m MaxRetryError(_pool, url, error [38;5;129;01mor[39;00m ResponseError(cause))
[0;32m    594[0m log[38;5;241m.[39mdebug([38;5;124m"[39m[38;5;124mIncremented Retry for (url=[39m[38;5;124m'[39m[38;5;132;01m%s[39;00m[38;5;124m'[39m[38;5;124m): [39m[38;5;132;01m%r[39;00m[38;5;124m"[39m, url, new_retry)

[1;31mMaxRetryError[0m: HTTPSConnectionPool(host='gds-hsds-nsrdb-files.nrelcloud.org', port=443): Max retries exceeded with url: /data/solar/145809_39.73_-105.18_tmy-2020_ea1df904c51bb8de783905c5d872379c.csv (Caused by SSLError(SSLCertVerificationError(1, '[SSL: CERTIFICATE_VERIFY_FAILED] certificate verify failed: self-signed certificate in certificate chain (_ssl.c:1006)')))

During handling of the above exception, another exception occurred:

[1;31mSSLError[0m                                  Traceback (most recent call last)
Cell [1;32mIn[5], line 1[0m
[1;32m----> 1[0m df_tmy, metadata [38;5;241m=[39m pvlib[38;5;241m.[39miotools[38;5;241m.[39mget_psm3(
[0;32m      2[0m     latitude[38;5;241m=[39m[38;5;241m39.7407[39m, longitude[38;5;241m=[39m[38;5;241m-[39m[38;5;241m105.1686[39m,
[0;32m      3[0m     api_key[38;5;241m=[39mNREL_API_KEY,
[0;32m      4[0m     email[38;5;241m=[39m[38;5;124m'[39m[38;5;124msilvana.ovaitt@nrel.gov[39m[38;5;124m'[39m,  [38;5;66;03m# <-- any email works here fine[39;00m
[0;32m      5[0m     names[38;5;241m=[39m[38;5;124m'[39m[38;5;124mtmy[39m[38;5;124m'[39m)
[0;32m      6[0m metadata

File [1;32m~\Documents\GitHub\pvlib-python\pvlib\iotools\psm3.py:215[0m, in [0;36mget_psm3[1;34m(latitude, longitude, api_key, email, names, interval, attributes, leap_day, full_name, affiliation, map_variables, url, timeout)[0m
[0;32m    212[0m     [38;5;28;01melse[39;00m:
[0;32m    213[0m         url [38;5;241m=[39m PSM_URL
[1;32m--> 215[0m response [38;5;241m=[39m requests[38;5;241m.[39mget(url, params[38;5;241m=[39mparams, timeout[38;5;241m=[39mtimeout)
[0;32m    216[0m [38;5;28;01mif[39;00m [38;5;129;01mnot[39;00m response[38;5;241m.[39mok:
[0;32m    217[0m     [38;5;66;03m# if the API key is rejected, then the response status will be 403[39;00m
[0;32m    218[0m     [38;5;66;03m# Forbidden, and then the error is in the content and there is no JSON[39;00m
[0;32m    219[0m     [38;5;28;01mtry[39;00m:

File [1;32m~\AppData\Roaming\Python\Python311\site-packages\requests\api.py:73[0m, in [0;36mget[1;34m(url, params, **kwargs)[0m
[0;32m     62[0m [38;5;28;01mdef[39;00m [38;5;21mget[39m(url, params[38;5;241m=[39m[38;5;28;01mNone[39;00m, [38;5;241m*[39m[38;5;241m*[39mkwargs):
[0;32m     63[0m [38;5;250m    [39m[38;5;124mr[39m[38;5;124;03m"""Sends a GET request.[39;00m
[0;32m     64[0m 
[0;32m     65[0m [38;5;124;03m    :param url: URL for the new :class:`Request` object.[39;00m
[1;32m   (...)[0m
[0;32m     70[0m [38;5;124;03m    :rtype: requests.Response[39;00m
[0;32m     71[0m [38;5;124;03m    """[39;00m
[1;32m---> 73[0m     [38;5;28;01mreturn[39;00m request([38;5;124m"[39m[38;5;124mget[39m[38;5;124m"[39m, url, params[38;5;241m=[39mparams, [38;5;241m*[39m[38;5;241m*[39mkwargs)

File [1;32m~\AppData\Roaming\Python\Python311\site-packages\requests\api.py:59[0m, in [0;36mrequest[1;34m(method, url, **kwargs)[0m
[0;32m     55[0m [38;5;66;03m# By using the 'with' statement we are sure the session is closed, thus we[39;00m
[0;32m     56[0m [38;5;66;03m# avoid leaving sockets open which can trigger a ResourceWarning in some[39;00m
[0;32m     57[0m [38;5;66;03m# cases, and look like a memory leak in others.[39;00m
[0;32m     58[0m [38;5;28;01mwith[39;00m sessions[38;5;241m.[39mSession() [38;5;28;01mas[39;00m session:
[1;32m---> 59[0m     [38;5;28;01mreturn[39;00m session[38;5;241m.[39mrequest(method[38;5;241m=[39mmethod, url[38;5;241m=[39murl, [38;5;241m*[39m[38;5;241m*[39mkwargs)

File [1;32m~\AppData\Roaming\Python\Python311\site-packages\requests\sessions.py:589[0m, in [0;36mSession.request[1;34m(self, method, url, params, data, headers, cookies, files, auth, timeout, allow_redirects, proxies, hooks, stream, verify, cert, json)[0m
[0;32m    584[0m send_kwargs [38;5;241m=[39m {
[0;32m    585[0m     [38;5;124m"[39m[38;5;124mtimeout[39m[38;5;124m"[39m: timeout,
[0;32m    586[0m     [38;5;124m"[39m[38;5;124mallow_redirects[39m[38;5;124m"[39m: allow_redirects,
[0;32m    587[0m }
[0;32m    588[0m send_kwargs[38;5;241m.[39mupdate(settings)
[1;32m--> 589[0m resp [38;5;241m=[39m [38;5;28mself[39m[38;5;241m.[39msend(prep, [38;5;241m*[39m[38;5;241m*[39msend_kwargs)
[0;32m    591[0m [38;5;28;01mreturn[39;00m resp

File [1;32m~\AppData\Roaming\Python\Python311\site-packages\requests\sessions.py:725[0m, in [0;36mSession.send[1;34m(self, request, **kwargs)[0m
[0;32m    722[0m [38;5;28;01mif[39;00m allow_redirects:
[0;32m    723[0m     [38;5;66;03m# Redirect resolving generator.[39;00m
[0;32m    724[0m     gen [38;5;241m=[39m [38;5;28mself[39m[38;5;241m.[39mresolve_redirects(r, request, [38;5;241m*[39m[38;5;241m*[39mkwargs)
[1;32m--> 725[0m     history [38;5;241m=[39m [resp [38;5;28;01mfor[39;00m resp [38;5;129;01min[39;00m gen]
[0;32m    726[0m [38;5;28;01melse[39;00m:
[0;32m    727[0m     history [38;5;241m=[39m []

File [1;32m~\AppData\Roaming\Python\Python311\site-packages\requests\sessions.py:725[0m, in [0;36m<listcomp>[1;34m(.0)[0m
[0;32m    722[0m [38;5;28;01mif[39;00m allow_redirects:
[0;32m    723[0m     [38;5;66;03m# Redirect resolving generator.[39;00m
[0;32m    724[0m     gen [38;5;241m=[39m [38;5;28mself[39m[38;5;241m.[39mresolve_redirects(r, request, [38;5;241m*[39m[38;5;241m*[39mkwargs)
[1;32m--> 725[0m     history [38;5;241m=[39m [resp [38;5;28;01mfor[39;00m resp [38;5;129;01min[39;00m gen]
[0;32m    726[0m [38;5;28;01melse[39;00m:
[0;32m    727[0m     history [38;5;241m=[39m []

File [1;32m~\AppData\Roaming\Python\Python311\site-packages\requests\sessions.py:266[0m, in [0;36mSessionRedirectMixin.resolve_redirects[1;34m(self, resp, req, stream, timeout, verify, cert, proxies, yield_requests, **adapter_kwargs)[0m
[0;32m    263[0m     [38;5;28;01myield[39;00m req
[0;32m    264[0m [38;5;28;01melse[39;00m:
[1;32m--> 266[0m     resp [38;5;241m=[39m [38;5;28mself[39m[38;5;241m.[39msend(
[0;32m    267[0m         req,
[0;32m    268[0m         stream[38;5;241m=[39mstream,
[0;32m    269[0m         timeout[38;5;241m=[39mtimeout,
[0;32m    270[0m         verify[38;5;241m=[39mverify,
[0;32m    271[0m         cert[38;5;241m=[39mcert,
[0;32m    272[0m         proxies[38;5;241m=[39mproxies,
[0;32m    273[0m         allow_redirects[38;5;241m=[39m[38;5;28;01mFalse[39;00m,
[0;32m    274[0m         [38;5;241m*[39m[38;5;241m*[39madapter_kwargs,
[0;32m    275[0m     )
[0;32m    277[0m     extract_cookies_to_jar([38;5;28mself[39m[38;5;241m.[39mcookies, prepared_request, resp[38;5;241m.[39mraw)
[0;32m    279[0m     [38;5;66;03m# extract redirect url, if any, for the next loop[39;00m

File [1;32m~\AppData\Roaming\Python\Python311\site-packages\requests\sessions.py:703[0m, in [0;36mSession.send[1;34m(self, request, **kwargs)[0m
[0;32m    700[0m start [38;5;241m=[39m preferred_clock()
[0;32m    702[0m [38;5;66;03m# Send the request[39;00m
[1;32m--> 703[0m r [38;5;241m=[39m adapter[38;5;241m.[39msend(request, [38;5;241m*[39m[38;5;241m*[39mkwargs)
[0;32m    705[0m [38;5;66;03m# Total elapsed time of the request (approximately)[39;00m
[0;32m    706[0m elapsed [38;5;241m=[39m preferred_clock() [38;5;241m-[39m start

File [1;32m~\AppData\Roaming\Python\Python311\site-packages\requests\adapters.py:517[0m, in [0;36mHTTPAdapter.send[1;34m(self, request, stream, timeout, verify, cert, proxies)[0m
[0;32m    513[0m         [38;5;28;01mraise[39;00m ProxyError(e, request[38;5;241m=[39mrequest)
[0;32m    515[0m     [38;5;28;01mif[39;00m [38;5;28misinstance[39m(e[38;5;241m.[39mreason, _SSLError):
[0;32m    516[0m         [38;5;66;03m# This branch is for urllib3 v1.22 and later.[39;00m
[1;32m--> 517[0m         [38;5;28;01mraise[39;00m SSLError(e, request[38;5;241m=[39mrequest)
[0;32m    519[0m     [38;5;28;01mraise[39;00m [38;5;167;01mConnectionError[39;00m(e, request[38;5;241m=[39mrequest)
[0;32m    521[0m [38;5;28;01mexcept[39;00m ClosedPoolError [38;5;28;01mas[39;00m e:

[1;31mSSLError[0m: HTTPSConnectionPool(host='gds-hsds-nsrdb-files.nrelcloud.org', port=443): Max retries exceeded with url: /data/solar/145809_39.73_-105.18_tmy-2020_ea1df904c51bb8de783905c5d872379c.csv (Caused by SSLError(SSLCertVerificationError(1, '[SSL: CERTIFICATE_VERIFY_FAILED] certificate verify failed: self-signed certificate in certificate chain (_ssl.c:1006)')))

