Traceback (most recent call last):
  File "C:\Users\sayala\AppData\Roaming\Python\Python311\site-packages\jupyter_cache\executors\utils.py", line 58, in single_nb_execution
    executenb(
  File "C:\ProgramData\Anaconda3\Lib\site-packages\nbclient\client.py", line 1204, in execute
    return NotebookClient(nb=nb, resources=resources, km=km, **kwargs).execute()
           ^^^^^^^^^^^^^^^^^^^^^^^^^^^^^^^^^^^^^^^^^^^^^^^^^^^^^^^^^^^^^^^^^^^^^
  File "C:\ProgramData\Anaconda3\Lib\site-packages\nbclient\util.py", line 84, in wrapped
    return just_run(coro(*args, **kwargs))
           ^^^^^^^^^^^^^^^^^^^^^^^^^^^^^^^
  File "C:\ProgramData\Anaconda3\Lib\site-packages\nbclient\util.py", line 62, in just_run
    return loop.run_until_complete(coro)
           ^^^^^^^^^^^^^^^^^^^^^^^^^^^^^
  File "C:\ProgramData\Anaconda3\Lib\asyncio\base_events.py", line 653, in run_until_complete
    return future.result()
           ^^^^^^^^^^^^^^^
  File "C:\ProgramData\Anaconda3\Lib\site-packages\nbclient\client.py", line 663, in async_execute
    await self.async_execute_cell(
  File "C:\ProgramData\Anaconda3\Lib\site-packages\nbclient\client.py", line 965, in async_execute_cell
    await self._check_raise_for_error(cell, cell_index, exec_reply)
  File "C:\ProgramData\Anaconda3\Lib\site-packages\nbclient\client.py", line 862, in _check_raise_for_error
    raise CellExecutionError.from_cell_and_msg(cell, exec_reply_content)
nbclient.exceptions.CellExecutionError: An error occurred while executing the following cell:
------------------
## 0. Setup 

%%bash
wget https://github.com/LBNL-ETA/Radiance/releases/download/012cb178/Radiance_012cb178_Linux.zip -O radiance.zip
unzip radiance.zip
tar -xvf radiance-5.3.012cb17835-Linux.tar.gz;

------------------

[1;36m  Cell [1;32mIn[1], line 4[1;36m[0m
[1;33m    wget https://github.com/LBNL-ETA/Radiance/releases/download/012cb178/Radiance_012cb178_Linux.zip -O radiance.zip[0m
[1;37m                                                                ^[0m
[1;31mSyntaxError[0m[1;31m:[0m leading zeros in decimal integer literals are not permitted; use an 0o prefix for octal integers

SyntaxError: leading zeros in decimal integer literals are not permitted; use an 0o prefix for octal integers (2748821830.py, line 4)

